---
title: "'Catch' não pode aparecer após 'Finally' dentro da instrução 'Try'"
ms.date: 07/20/2015
f1_keywords:
- vbc30379
- bc30379
helpviewer_keywords:
- BC30379
ms.assetid: 33d1278b-cf10-4c66-aaf8-08a4372f370b
ms.openlocfilehash: ab300d332dd82870901aec9bd57d8d5d8081a533
ms.sourcegitcommit: f8c270376ed905f6a8896ce0fe25b4f4b38ff498
ms.translationtype: MT
ms.contentlocale: pt-BR
ms.lasthandoff: 06/04/2020
ms.locfileid: "84403765"
---
# <a name="catch-cannot-appear-after-finally-within-a-try-statement"></a>'Catch' não pode aparecer após 'Finally' dentro da instrução 'Try'
Uma `Catch` instrução aparece no código após o `Finally` encerramento de um `Try` bloco de instrução. `Catch`deve aparecer dentro de um `Try...Catch...Finally` bloco de instruções.  
  
 **ID do erro:** BC30379  
  
## <a name="to-correct-this-error"></a>Para corrigir este erro  
  
1. Mova a `Catch` instrução para um local mais apropriado no código.  
  
## <a name="see-also"></a>Confira também

- [Instrução Try...Catch...Finally](../language-reference/statements/try-catch-finally-statement.md)
